Workbook

Sheet deutsch
A1: Variablencode | B1: (abgeleitet von) Frage(n) aus Haushaltsfragebogen ( HH ) / Personenfragebogen ( IND ) | C1: Variablenname | D1: Ausprägungen | F1: Wer bekommt die Frage gestellt / Filter | G1: Merkmal auf Hauhalts- / Personenebene
A2: HID | C2: Eindeutige Haushaltskennung | D2: 10001-12291 | F2: Alle | G2: Haushalt
A3: PID | C3: Personenkennung | D3: 1-7 | F3: Alle | G3: Personen
A4: TIME_PERIOD | C4: HETUS-Welle | D4: 2020 | F4: Alle
A5: REF_AREA | C5: Land, das Daten erhebt | D5: AT | F5: Alle
A6: IND1 | B6: F2 (HH) | C6: Geschlecht | D6: 1 | E6: männlich | F6: Alle | G6: Personen
D7: 2 | E7: weiblich
A8: IND2 | B8: F2 (HH) | C8: Alter in Altergruppen | D8: 21 | E8: 0-2 Jahre | F8: Alle | G8: Personen
D9: 22 | E9: 3-5 Jahre
D10: 23 | E10: 6 Jahre
D11: 24 | E11: 7-9 Jahre
A12: IND3 | B12: F33 (IND) | C12: Geburtsland | D12: 1 | E12: Österreich | F12: Alle | G12: Personen
D13: 2 | E13: EU 14 außer Österreich
D14: 3 | E14: Die 13 restlichen EU Staaten
D15: 4 | E15: Ex-Jugoslawien außer Slowenien und Kroatien
D16: 5 | E16: Türkei
D17: 6 | E17: alle anderen
A18: IND4 | B18: F32 (IND) | C18: Staatsbürgerschaft | D18: 1 | E18: Österreich | F18: Alle | G18: Personen
D19: 2 | E19: EU 14 außer Österreich
D20: 3 | E20: Die 13 restlichen EU Staaten
D21: 4 | E21: Ex-Jugoslawien außer Slowenien und Kroatien
D22: 5 | E22: Türkei
D23: 6 | E23: alle anderen
A24: IND3_1 | B24: F34 (IND) | C24: Geburtsland des Vaters | D24: 1 | E24: Österreich | F24: Alle | G24: Personen
D25: 2 | E25: EU 14 außer Österreich
D26: 3 | E26: Die 13 restlichen EU Staaten
D27: 4 | E27: Ex-Jugoslawien außer Slowenien und Kroatien
D28: 5 | E28: Türkei
D29: 6 | E29: alle anderen
A30: IND3_2 | B30: F35 (IND) | C30: Geburtsland der Mutter | D30: 1 | E30: Österreich | F30: Alle | G30: Personen
D31: 2 | E31: EU 14 außer Österreich
D32: 3 | E32: Die 13 restlichen EU Staaten
D33: 4 | E33: Ex-Jugoslawien außer Slowenien und Kroatien
D34: 5 | E34: Türkei
D35: 6 | E35: alle anderen
A36: IND31 | B36: F36 (IND) | C36: Besuch von Krippe? | D36: 1 | E36: Ja | F36: Alter <= 3 | G36: Personen
D37: 2 | E37: Nein
D38: -1 | E38: Filter
A39: IND32 | B39: F39 (IND) | C39: Besuch von Kindergarten? | D39: 1 | E39: Ja | F39: Alter >=2 und <=6 sowie IND31 = 2, -1 | G39: Personen
D40: 2 | E40: Nein
...

Sheet englisch
A1: =_xlfn.TRANSLATE(deutsch!A1,"de","en") -> Variable code | B1: =_xlfn.TRANSLATE(deutsch!B1,"de","en") -> (derived from) Question(s) from Household Questionnaire ( HH ) / Personal Questionnaire ( IND ) | C1: =_xlfn.TRANSLATE(deutsch!C1,"de","en") -> Variable Name | D1: =_xlfn.TRANSLATE(deutsch!D1,"de","en") -> Characteristics | E1: =_xlfn.TRANSLATE(deutsch!E1,"de","en") | F1: =_xlfn.TRANSLATE(deutsch!F1,"de","en") -> Who gets asked the question / Filter | G1: =_xlfn.TRANSLATE(deutsch!G1,"de","en") -> Household/person-level feature
A2: =_xlfn.TRANSLATE(deutsch!A2,"de","en") -> HID | B2: =_xlfn.TRANSLATE(deutsch!B2,"de","en") | C2: =_xlfn.TRANSLATE(deutsch!C2,"de","en") -> Unique household identifier | D2: =_xlfn.TRANSLATE(deutsch!D2,"de","en") -> 10001-12291 | E2: =_xlfn.TRANSLATE(deutsch!E2,"de","en") | F2: =_xlfn.TRANSLATE(deutsch!F2,"de","en") -> All | G2: =_xlfn.TRANSLATE(deutsch!G2,"de","en") -> Household
A3: =_xlfn.TRANSLATE(deutsch!A3,"de","en") -> PGD | B3: =_xlfn.TRANSLATE(deutsch!B3,"de","en") | C3: =_xlfn.TRANSLATE(deutsch!C3,"de","en") -> Personal ID | D3: =_xlfn.TRANSLATE(deutsch!D3,"de","en") -> 1-7 | E3: =_xlfn.TRANSLATE(deutsch!E3,"de","en") | F3: =_xlfn.TRANSLATE(deutsch!F3,"de","en") -> All | G3: =_xlfn.TRANSLATE(deutsch!G3,"de","en") -> People
A4: =_xlfn.TRANSLATE(deutsch!A4,"de","en") -> TIME_PERIOD | B4: =_xlfn.TRANSLATE(deutsch!B4,"de","en") | C4: =_xlfn.TRANSLATE(deutsch!C4,"de","en") -> HETUS Wave | D4: =_xlfn.TRANSLATE(deutsch!D4,"de","en") -> 2020 | E4: =_xlfn.TRANSLATE(deutsch!E4,"de","en") | F4: =_xlfn.TRANSLATE(deutsch!F4,"de","en") -> All | G4: =_xlfn.TRANSLATE(deutsch!G4,"de","en")
A5: =_xlfn.TRANSLATE(deutsch!A5,"de","en") -> REF_AREA | B5: =_xlfn.TRANSLATE(deutsch!B5,"de","en") | C5: =_xlfn.TRANSLATE(deutsch!C5,"de","en") -> Country that collects data | D5: =_xlfn.TRANSLATE(deutsch!D5,"de","en") -> AT | E5: =_xlfn.TRANSLATE(deutsch!E5,"de","en") | F5: =_xlfn.TRANSLATE(deutsch!F5,"de","en") -> All | G5: =_xlfn.TRANSLATE(deutsch!G5,"de","en")
A6: =_xlfn.TRANSLATE(deutsch!A6,"de","en") -> IND1 | B6: =_xlfn.TRANSLATE(deutsch!B6,"de","en") -> F2 (HH) | C6: =_xlfn.TRANSLATE(deutsch!C6,"de","en") -> Gender | D6: =_xlfn.TRANSLATE(deutsch!D6,"de","en") -> 1 | E6: =_xlfn.TRANSLATE(deutsch!E6,"de","en") -> Male | F6: =_xlfn.TRANSLATE(deutsch!F6,"de","en") -> All | G6: =_xlfn.TRANSLATE(deutsch!G6,"de","en") -> People
A7: =_xlfn.TRANSLATE(deutsch!A7,"de","en") | B7: =_xlfn.TRANSLATE(deutsch!B7,"de","en") | C7: =_xlfn.TRANSLATE(deutsch!C7,"de","en") | D7: =_xlfn.TRANSLATE(deutsch!D7,"de","en") -> 2 | E7: =_xlfn.TRANSLATE(deutsch!E7,"de","en") -> Female | F7: =_xlfn.TRANSLATE(deutsch!F7,"de","en") | G7: =_xlfn.TRANSLATE(deutsch!G7,"de","en")
A8: =_xlfn.TRANSLATE(deutsch!A8,"de","en") -> IND2 | B8: =_xlfn.TRANSLATE(deutsch!B8,"de","en") -> F2 (HH) | C8: =_xlfn.TRANSLATE(deutsch!C8,"de","en") -> Age in age groups | D8: =_xlfn.TRANSLATE(deutsch!D8,"de","en") -> 21 | E8: =_xlfn.TRANSLATE(deutsch!E8,"de","en") -> 0-2 years | F8: =_xlfn.TRANSLATE(deutsch!F8,"de","en") -> All | G8: =_xlfn.TRANSLATE(deutsch!G8,"de","en") -> People
A9: =_xlfn.TRANSLATE(deutsch!A9,"de","en") | B9: =_xlfn.TRANSLATE(deutsch!B9,"de","en") | C9: =_xlfn.TRANSLATE(deutsch!C9,"de","en") | D9: =_xlfn.TRANSLATE(deutsch!D9,"de","en") -> 22 | E9: =_xlfn.TRANSLATE(deutsch!E9,"de","en") -> 3-5 years | F9: =_xlfn.TRANSLATE(deutsch!F9,"de","en") | G9: =_xlfn.TRANSLATE(deutsch!G9,"de","en")
A10: =_xlfn.TRANSLATE(deutsch!A10,"de","en") | B10: =_xlfn.TRANSLATE(deutsch!B10,"de","en") | C10: =_xlfn.TRANSLATE(deutsch!C10,"de","en") | D10: =_xlfn.TRANSLATE(deutsch!D10,"de","en") -> 23 | E10: =_xlfn.TRANSLATE(deutsch!E10,"de","en") -> 6 years | F10: =_xlfn.TRANSLATE(deutsch!F10,"de","en") | G10: =_xlfn.TRANSLATE(deutsch!G10,"de","en")
A11: =_xlfn.TRANSLATE(deutsch!A11,"de","en") | B11: =_xlfn.TRANSLATE(deutsch!B11,"de","en") | C11: =_xlfn.TRANSLATE(deutsch!C11,"de","en") | D11: =_xlfn.TRANSLATE(deutsch!D11,"de","en") -> 24 | E11: =_xlfn.TRANSLATE(deutsch!E11,"de","en") -> 7-9 years | F11: =_xlfn.TRANSLATE(deutsch!F11,"de","en") | G11: =_xlfn.TRANSLATE(deutsch!G11,"de","en")
A12: =_xlfn.TRANSLATE(deutsch!A12,"de","en") -> IND3 | B12: =_xlfn.TRANSLATE(deutsch!B12,"de","en") -> F33 (IND) | C12: =_xlfn.TRANSLATE(deutsch!C12,"de","en") -> Country of birth | D12: =_xlfn.TRANSLATE(deutsch!D12,"de","en") -> 1 | E12: =_xlfn.TRANSLATE(deutsch!E12,"de","en") -> Austria | F12: =_xlfn.TRANSLATE(deutsch!F12,"de","en") -> All | G12: =_xlfn.TRANSLATE(deutsch!G12,"de","en") -> People
... A97: =_xlfn.TRANSLATE(deutsch!A97,"de","en") | B97: =_xlfn.TRANSLATE(deutsch!B97,"de","en") | C97: =_xlfn.TRANSLATE(deutsch!C97,"de","en") | D97: =_xlfn.TRANSLATE(deutsch!D97,"de","en") -> 0 | E97: =_xlfn.TRANSLATE(deutsch!E97,"de","en") -> otherwise | F97: =_xlfn.TRANSLATE(deutsch!F97,"de","en") | G97: =_xlfn.TRANSLATE(deutsch!G97,"de","en")
